<?xml version="1.0" ?>
<!-- =================================================================================== -->
<!-- |    This document was autogenerated by xacro from vispa.xacro                    | -->
<!-- |    EDITING THIS FILE BY HAND IS NOT RECOMMENDED                                 | -->
<!-- =================================================================================== -->
<!--
   Copyright (C) Airbus Defence and Space Ltd - All Rights Reserved
   Written by Mark Shilton <mark.shilton@airbus.com>, January 2021

This is the master Locarm AD model file, in form of a XACRO macro.
To build the URDF file, invoke:
  rosrun xacro xacro.py locarm.xacro > locarm.urdf
  TODO: make this part of a build process
Joint FORs are consistent with LOCARM specification .
Joint FOR locations as well as arm dimensions have been cross-checked with arm specification.
Joint torques have been taken from arm specification.
Element masses have been taken from arm specification; inertia matrices have been generated with Meshlab (TODO).
(see http://gazebosim.org/tutorials?tut=inertia&cat=build_robot)
The file conforms to ros_industrial recommndations (TODO)
(see http://wiki.ros.org/Industrial/Tutorials/Create%20a%20URDF%20for%20an%20Industrial%20Robot)
 -->
<robot name="locarm" xmlns:xacro="http://www.ros.org/wiki/xacro">
  <!-- Xacro constants -->
  <!--Kg-->
  <!-- 1e-3 -->
  <!-- Xacro macros -->
  <!-- Include externals -->
  <!-- Import Gazebo-customization elements -->
  <!-- <xacro:include filename="$(find locarm_description)/urdf/locarm.gazebo" /> -->
  <!-- Standard ROS(-industrial) frames -->
  <!-- inertials not needed here -->
  <link name="base_link"/>
  <link name="base"/>
  <link name="world"/>
  <!-- <link name="tool0">
    <xacro:box_inertia mass="0.1" x="0.1" y="0.1" z="0.1" orig="0 0 0" />
  </link> -->
  <!-- Locarm links -->
  <link name="link0">
    <visual>
      <geometry>
        <mesh filename="package://vispa_description/meshes/LINK_BASE.stl" scale="0.001 0.001 0.001"/>
        <!-- Needed to scale as CAD exported in mm but rviz comsumes in SI units i.e. metres-->
      </geometry>
    </visual>
    <collision>
      <geometry>
        <mesh filename="package://vispa_description/meshes/LINK_BASE_col.stl" scale="0.001 0.001 0.001"/>
      </geometry>
    </collision>
    <inertial>
      <mass value="0.627"/>
      <inertia ixx="0.00281845585208" ixy="0" ixz="0" iyy="0.00281883333333" iyz="0" izz="0.00379978918542"/>
      <origin xyz="0 0 0.0"/>
    </inertial>
  </link>
  <link name="link1">
    <visual>
      <geometry>
        <mesh filename="package://vispa_description/meshes/LINK_0.stl" scale="0.001 0.001 0.001"/>
      </geometry>
    </visual>
    <collision>
      <geometry>
        <mesh filename="package://vispa_description/meshes/LINK_0_col.stl" scale="0.001 0.001 0.001"/>
      </geometry>
    </collision>
    <inertial>
      <mass value="1.5"/>
      <inertia ixx="0.00823683333333" ixy="0" ixz="0" iyy="0.00821708333333" iyz="0" izz="0.00234041666667"/>
      <origin xyz="0.0 -0.004173 0.032607"/>
    </inertial>
  </link>
  <link name="link2">
    <visual>
      <geometry>
        <mesh filename="package://vispa_description/meshes/LINK_1.stl" scale="0.001 0.001 0.001"/>
      </geometry>
    </visual>
    <collision>
      <geometry>
        <mesh filename="package://vispa_description/meshes/LINK_1_col.stl" scale="0.001 0.001 0.001"/>
      </geometry>
    </collision>
    <inertial>
      <mass value="2.5"/>
      <inertia ixx="0.0988689375" ixy="0" ixz="0" iyy="0.00683708333333" iyz="0" izz="0.0943525208333"/>
      <origin xyz="0.0 0.219495 0.063379"/>
    </inertial>
  </link>
  <link name="link3">
    <visual>
      <geometry>
        <mesh filename="package://vispa_description/meshes/LINK_2.stl" scale="0.001 0.001 0.001"/>
      </geometry>
    </visual>
    <collision>
      <geometry>
        <mesh filename="package://vispa_description/meshes/LINK_2_col.stl" scale="0.001 0.001 0.001"/>
      </geometry>
    </collision>
    <inertial>
      <mass value="1.863"/>
      <inertia ixx="0.00319248023008" ixy="0" ixz="0" iyy="0.00305781356342" iyz="0" izz="0.00170283333333"/>
      <origin xyz="0.0 0.003751 -0.066289"/>
    </inertial>
  </link>
  <link name="link4">
    <visual>
      <geometry>
        <mesh filename="package://vispa_description/meshes/LINK_3.stl" scale="0.001 0.001 0.001"/>
      </geometry>
    </visual>
    <collision>
      <geometry>
        <mesh filename="package://vispa_description/meshes/LINK_3_col.stl" scale="0.001 0.001 0.001"/>
      </geometry>
    </collision>
    <inertial>
      <mass value="2.16"/>
      <inertia ixx="0.0555065850083" ixy="0" ixz="0" iyy="0.0538596631441" iyz="0" izz="0.00269958148575"/>
      <origin xyz="-0.000267 0.040905 0.237073"/>
    </inertial>
  </link>
  <link name="link5">
    <visual>
      <geometry>
        <mesh filename="package://vispa_description/meshes/LINK_4.stl" scale="0.001 0.001 0.001"/>
      </geometry>
    </visual>
    <collision>
      <geometry>
        <mesh filename="package://vispa_description/meshes/LINK_4_col.stl" scale="0.001 0.001 0.001"/>
      </geometry>
    </collision>
    <inertial>
      <mass value="1.5"/>
      <inertia ixx="0.00242821141742" ixy="0" ixz="0" iyy="0.00212303984967" iyz="0" izz="0.00134496960042"/>
      <origin xyz="0.0 0.003134 0.063172"/>
    </inertial>
  </link>
  <link name="link6">
    <visual>
      <geometry>
        <mesh filename="package://vispa_description/meshes/LINK_5.stl" scale="0.001 0.001 0.001"/>
      </geometry>
    </visual>
    <collision>
      <geometry>
        <mesh filename="package://vispa_description/meshes/LINK_5_col.stl" scale="0.001 0.001 0.001"/>
      </geometry>
    </collision>
    <inertial>
      <mass value="1.7"/>
      <inertia ixx="0.00327423958542" ixy="0" ixz="0" iyy="0.00327403159742" iyz="0" izz="0.00180245867867"/>
      <origin xyz="0.000244 0.0 0.084854"/>
    </inertial>
  </link>
  <!-- Standard ROS(-industrial) and Gazebo joints -->
  <joint name="base_link-link0" type="fixed">
    <parent link="base_link"/>
    <child link="link0"/>
    <!-- <origin xyz="0 0 0" rpy="0 0 ${2*C_1_DEGREE}"/> -->
  </joint>
  <joint name="base_link-base" type="fixed">
    <parent link="base_link"/>
    <child link="base"/>
    <!-- <origin xyz="0 0 0" /> -->
  </joint>
  <joint name="world-base_link" type="fixed">
    <parent link="world"/>
    <child link="base_link"/>
    <!-- <origin xyz="0 0 0" /> -->
  </joint>
   --&gt;

  
  <!--<joint name="link6-tool0" type="fixed">
  	<parent link="link6" />
  	<child link="tool0" />
  	<origin xyz="0 0 0.1685" />
  </joint>
  -->
  <!-- LOCARM joints -->
  <joint name="j01" type="revolute">
    <axis xyz="0 0 1"/>
    <limit effort="50" lower="-3.14149265359" upper="3.14149265359" velocity="0.09395689"/>
    <parent link="link0"/>
    <child link="link1"/>
    <!-- Location of the link1 FOR in link0 FOR + compensation for as-built 0 position of the joint -->
    <!--origin xyz="0 0 0.105" /-->
    <origin rpy="0 0 0" xyz="0.0 0.0 0.0048"/>
    <dynamics damping="100"/>
  </joint>
  <joint name="j12" type="revolute">
    <axis xyz="0 -1 0"/>
    <limit effort="50" lower="-1.5707963268" upper="1.5707963268" velocity="0.09395689"/>
    <parent link="link1"/>
    <child link="link2"/>
    <!-- Location of the link2 FOR in link1 FOR + compensation for as-built 0 position of the joint -->
    <origin rpy="0 -1.5707963268 0" xyz="0.005 -0.075 0.135"/>
     --&gt;
    
    <dynamics damping="100"/>
  </joint>
  <joint name="j23" type="revolute">
    <axis xyz="0 1 0"/>
    <limit effort="50" lower="-3.14149265359" upper="3.14149265359" velocity="0.09395689"/>
    <parent link="link2"/>
    <child link="link3"/>
    <!-- Location of the link3 FOR in link2 FOR  + compensation for as-built 0 position of the joint -->
    <!--origin xyz="0 0.95 0.067" /-->
    <origin rpy="0 0 0" xyz="0.667 -0.022 0.0"/>
    <dynamics damping="100"/>
  </joint>
  <joint name="j34" type="revolute">
    <axis xyz="-1 0 0"/>
    <limit effort="50" lower="-3.14149265359" upper="3.14149265359" velocity="0.09395689"/>
    <parent link="link3"/>
    <child link="link4"/>
    <!-- Location of the link4 FOR in link3 FOR  + compensation for as-built 0 position of the joint -->
    <!-- origin xyz="0 0.0565 -0.127" rpy="${-C_PI_2} 0 0" /-->
    <origin rpy="0 0 0" xyz="-0.113 0.08 0.0"/>
    <dynamics damping="100"/>
  </joint>
  <joint name="j45" type="revolute">
    <axis xyz="0 1 0"/>
    <limit effort="50" lower="-3.14149265359" upper="3.14149265359" velocity="0.09395689"/>
    <parent link="link4"/>
    <child link="link5"/>
    <!-- Location of the link5 FOR in link4 FOR + compensation for as-built 0 position of the joint -->
    <!-- origin xyz="0 0.0455 0.7635" rpy="${C_PI_2} 0 0" /-->
    <origin rpy="0 0 0" xyz="-0.435 0.03 0.0"/>
    <dynamics damping="100"/>
  </joint>
  <joint name="j56" type="revolute">
    <axis xyz="0 0 -1"/>
    <limit effort="50" lower="-3.14149265359" upper="3.14149265359" velocity="0.09395689"/>
    <parent link="link5"/>
    <child link="link6"/>
    <!-- Location of the link6 FOR in link5 FOR + compensation for as-built 0 position of the joint -->
    <origin rpy="0 1.5707963268 0" xyz="0.237 -0.021 0.0"/>
    <dynamics damping="100"/>
  </joint>
  <!-- Transmissions (ros_control) -->
  <transmission name="j01_t">
    <type>transmission_interface/SimpleTransmission</type>
    <joint name="j01">
      <hardwareInterface>EffortJointInterface</hardwareInterface>
    </joint>
    <actuator name="motor_j01">
      <mechanicalReduction>1</mechanicalReduction>
    </actuator>
  </transmission>
  <transmission name="j12_t">
    <type>transmission_interface/SimpleTransmission</type>
    <joint name="j12">
      <hardwareInterface>EffortJointInterface</hardwareInterface>
    </joint>
    <actuator name="motor_j12">
      <mechanicalReduction>1</mechanicalReduction>
    </actuator>
  </transmission>
  <transmission name="j23_t">
    <type>transmission_interface/SimpleTransmission</type>
    <joint name="j23">
      <hardwareInterface>EffortJointInterface</hardwareInterface>
    </joint>
    <actuator name="motor_j23">
      <mechanicalReduction>1</mechanicalReduction>
    </actuator>
  </transmission>
  <transmission name="j34_t">
    <type>transmission_interface/SimpleTransmission</type>
    <joint name="j34">
      <hardwareInterface>EffortJointInterface</hardwareInterface>
    </joint>
    <actuator name="motor_j34">
      <mechanicalReduction>1</mechanicalReduction>
    </actuator>
  </transmission>
  <transmission name="j45_t">
    <type>transmission_interface/SimpleTransmission</type>
    <joint name="j45">
      <hardwareInterface>EffortJointInterface</hardwareInterface>
    </joint>
    <actuator name="motor_j45">
      <mechanicalReduction>1</mechanicalReduction>
    </actuator>
  </transmission>
  <transmission name="j56_t">
    <type>transmission_interface/SimpleTransmission</type>
    <joint name="j56">
      <hardwareInterface>EffortJointInterface</hardwareInterface>
    </joint>
    <actuator name="motor_j56">
      <mechanicalReduction>1</mechanicalReduction>
    </actuator>
  </transmission>
</robot>

